<?xml version="1.0"?>

<robot name="virtual_robot" xmlns:xacro="http://www.ros.org/wiki/xacro">

  <!-- Global namespace -->
  <xacro:arg name="robot_name" default="car_1" />
  <xacro:arg name="robot_skin" default="Blue" />

  <!-- inertial parameter macros -->

  <xacro:macro name="box_inertia" params="m w h d">
    <inertial>
      <origin xyz="0 0 0" rpy="${pi/2} 0 ${pi/2}"/>
      <mass value="${m}"/>
      <inertia ixx="${(m/12) * (h*h + d*d)}" ixy="0.0" ixz="0.0" iyy="${(m/12) * (w*w + d*d)}" iyz="0.0" izz="${(m/12) * (w*w + h*h)}"/>
    </inertial>
  </xacro:macro>

  <xacro:macro name="chassis_inertial_params">
    <origin xyz="0.1477 0 0" rpy="0 0 0" />
    <mass value="4.0" />
    <inertia ixx="0.010609" ixy="0"          ixz="0"
                            iyy="0.050409"   iyz="0"
                                             izz="0.05865" />
  </xacro:macro>

  <xacro:macro name="left_wheels_inertial_params">
    <origin xyz="0 0 -0.0225" rpy="0 0 0" />
    <mass value="0.34055" />
    <inertia ixx="0.00026046" ixy="0"          ixz="0"
                              iyy="0.00026046" iyz="0"
                                               izz="0.00041226" />
  </xacro:macro>

  <xacro:macro name="right_wheels_inertial_params">
    <origin xyz="0 0 0.0225" rpy="0 0 0" />
    <mass value="0.34055" />
    <inertia ixx="0.00026046" ixy="0"          ixz="0"
                              iyy="0.00026046" iyz="0"
                                               izz="0.00041226" />
  </xacro:macro>

  <xacro:macro name="steering_hinge_inertial_params">
    <origin xyz="0 0 0" rpy="0 0 0" />
    <mass value="0.100" />
    <inertia ixx="4E-06" ixy="0"           ixz="0"
                              iyy="4E-06"  iyz="0"
                                                izz="4E-06" />
  </xacro:macro>

  <xacro:macro name="hokuyo_inertial_params">
    <origin xyz="0 0 0" rpy="0 0 0" />
    <mass value="0.130" />
    <inertia ixx="4E-06" ixy="0"           ixz="0"
                              iyy="4E-06"  iyz="0"
                                                izz="4E-06" />
  </xacro:macro>


  <!-- geometry macros -->

  <xacro:macro name="chassis_geometry">
    <origin xyz="0.46 -0.135 -0.180" rpy="1.57 0 3.14" />
    <geometry>
      <mesh filename="model://urdf/meshes/chassis.stl" scale="0.000990 0.0009375 0.0009375"/>
    </geometry>
  </xacro:macro>


  <xacro:macro name="left_rear_wheel_geometry">
    <origin xyz="0 0 0" rpy="0 0 0" />
    <geometry>
      <mesh filename="model://urdf/meshes/left_wheel.stl" />
    </geometry>
  </xacro:macro>

  <xacro:macro name="right_rear_wheel_geometry">
    <origin xyz="0 0 0" rpy="0 0 0" />
    <geometry>
      <mesh filename="model://urdf/meshes/right_wheel.stl" />
    </geometry>
  </xacro:macro>

  <xacro:macro name="left_front_wheel_geometry">
    <origin xyz="0 0 0" rpy="0 0 0" />
    <geometry>
      <mesh filename="model://urdf/meshes/left_wheel.stl" />
    </geometry>
  </xacro:macro>

  <xacro:macro name="right_front_wheel_geometry">
    <origin xyz="0 0 0" rpy="0 0 0" />
    <geometry>
      <mesh filename="model://urdf/meshes/right_wheel.stl" />
    </geometry>
  </xacro:macro>

  <xacro:macro name="left_steering_hinge_geometry">
    <origin xyz="0 0 0" rpy="0 0 0" />
    <geometry>
      <mesh filename="model://urdf/meshes/hinge.stl" />
    </geometry>
  </xacro:macro>

  <xacro:macro name="right_steering_hinge_geometry">
    <origin xyz="0 0 0" rpy="0 0 0" />
    <geometry>
      <mesh filename="model://urdf/meshes/hinge.stl" />
    </geometry>
  </xacro:macro>

  <xacro:macro name="left_wheels_collision_geometry">
    <origin xyz="0 0 -0.0225" rpy="0 0 0" />
    <geometry>
      <cylinder length="0.045" radius="0.05" />
    </geometry>
  </xacro:macro>

  <xacro:macro name="right_wheels_collision_geometry">
    <origin xyz="0 0 0.0225" rpy="0 0 0" />
    <geometry>
      <cylinder length="0.045" radius="0.05" />
    </geometry>
  </xacro:macro>

  <!-- transmission macros -->

  <xacro:macro name="wheel_transmission" params="name">
    <ros2_control name="${name}_transmission" type="actuator">
      <hardware>
        <plugin>gz_ros2_control/GazeboSimSystem</plugin>
      </hardware>
      <joint name="${name}_joint">
        <command_interface name="velocity" />
        <state_interface name="velocity" />
        <state_interface name="position" />
      </joint>
    </ros2_control>
  </xacro:macro>

  <xacro:macro name="steering_hinge_transmission" params="name">
    <ros2_control name="${name}_transmission" type="actuator">
      <hardware>
        <plugin>gz_ros2_control/GazeboSimSystem</plugin>
      </hardware>
      <joint name="${name}_joint">
        <command_interface name="position" />
        <state_interface name="position" />
      </joint>
    </ros2_control>
  </xacro:macro>

  <!-- Add chassis and it's inertia link -->

  <link name="base_link"/>

  <link name="chassis">
    <visual>
      <xacro:chassis_geometry/>
      <material name="red" />
    </visual>
    <collision>
      <xacro:chassis_geometry />
    </collision>
  </link>

  <joint name="base_link_joint" type="fixed">
    <origin xyz="0 0 0.05" rpy="0 0 0" />
    <parent link="base_link" />
    <child link="chassis" />
  </joint>

  <link name="chassis_inertia">
    <inertial>
      <xacro:chassis_inertial_params />
    </inertial>
  </link>

  <joint name="chassis_inertia_joint" type="fixed">
    <origin xyz="0 0 0" rpy="0 0 0" />
    <parent link="chassis" />
    <child link="chassis_inertia" />
  </joint>

  <!-- Add the imu sensor -->
  <link name="imu_link">
    <visual>
      <geometry>
        <box size="0.1 0.1 0.1"/>
      </geometry>
    </visual>

    <collision>
      <geometry>
        <box size="0.1 0.1 0.1"/>
      </geometry>
    </collision>

    <xacro:box_inertia m="0.1" w="0.1" d="0.1" h="0.1"/>
  </link>

  <joint name="imu_joint" type="fixed">
    <parent link="base_link"/>
    <child link="imu_link"/>
    <origin xyz="0 0 0.01"/>
  </joint>

  <!-- Add the left rear wheel with its joints and tranmissions -->

  <link name="left_rear_wheel">
    <inertial>
      <xacro:left_wheels_inertial_params />
    </inertial>
    <visual>
      <xacro:left_rear_wheel_geometry />
      <material name="black" />
    </visual>
    <collision>
      <xacro:left_wheels_collision_geometry />
    </collision>
  </link>

  <joint name="left_rear_wheel_joint" type="continuous">
    <origin xyz="0 0.1 0" rpy="1.5708 0 0" />
    <parent link="chassis" />
    <child link="left_rear_wheel" />
    <axis xyz="0 0 -1" />
    <limit effort="10" velocity="100" />
  </joint>

  <xacro:wheel_transmission name="left_rear_wheel" />

  <!-- Add the right rear wheel with its joints and tranmissions -->

  <link name="right_rear_wheel">
    <inertial>
      <xacro:right_wheels_inertial_params />
    </inertial>
    <visual>
      <xacro:right_rear_wheel_geometry />
      <material name="black" />
    </visual>
    <collision>
      <xacro:right_wheels_collision_geometry />
    </collision>
  </link>

  <joint name="right_rear_wheel_joint" type="continuous">
    <origin xyz="0 -0.1 0" rpy="1.5708 0 0" />
    <parent link="chassis" />
    <child link="right_rear_wheel" />
    <axis xyz="0 0 -1" />
    <limit effort="10" velocity="100" />
  </joint>

  <xacro:wheel_transmission name="right_rear_wheel" />

  <!-- Add the left steering hinge with its joints and tranmissions -->

  <link name="left_steering_hinge">
    <inertial>
      <xacro:steering_hinge_inertial_params />
    </inertial>
    <visual>
      <xacro:left_steering_hinge_geometry />
      <material name="grey" />
    </visual>
  </link>

  <joint name="left_steering_hinge_joint" type="revolute">
    <origin xyz="0.325 0.1 0" rpy="0 1.5708 0" />
    <parent link="chassis" />
    <child link="left_steering_hinge" />
    <axis xyz="-1 0 0" />
    <limit lower="-1.0" upper="1.0" effort="10" velocity="100" />
  </joint>

  <xacro:steering_hinge_transmission name="left_steering_hinge" />

  <!-- Add the right steering hinge with its joints and tranmissions -->

  <link name="right_steering_hinge">
    <inertial>
      <xacro:steering_hinge_inertial_params />
    </inertial>
    <visual>
      <xacro:right_steering_hinge_geometry />
      <material name="grey" />
    </visual>
  </link>

  <joint name="right_steering_hinge_joint" type="revolute">
    <origin xyz="0.325 -0.1 0" rpy="0 1.5708 0" />
    <parent link="chassis" />
    <child link="right_steering_hinge" />
    <axis xyz="-1 0 0" />
    <limit lower="-1.0" upper="1.0" effort="10" velocity="100" />
  </joint>

  <xacro:steering_hinge_transmission name="right_steering_hinge" />

  <!-- Add the left front wheel with its joints and tranmissions -->

  <link name="left_front_wheel">
    <inertial>
      <xacro:left_wheels_inertial_params />
    </inertial>
    <visual>
      <xacro:left_front_wheel_geometry />
      <material name="black" />
    </visual>
    <collision>
      <xacro:left_wheels_collision_geometry />
    </collision>
  </link>

  <joint name="left_front_wheel_joint" type="continuous">
    <origin xyz="0 0 0" rpy="1.5708 0 0" />
    <parent link="left_steering_hinge" />
    <child link="left_front_wheel" />
    <axis xyz="0 0 -1" />
    <limit effort="10" velocity="100" />
  </joint>

  <xacro:wheel_transmission name="left_front_wheel" />

  <!-- Add the left front wheel with its joints and tranmissions -->

  <link name="right_front_wheel">
    <inertial>
      <xacro:right_wheels_inertial_params />
    </inertial>
    <visual>
      <xacro:right_front_wheel_geometry />
      <material name="black" />
    </visual>
    <collision>
      <xacro:right_wheels_collision_geometry />
    </collision>
  </link>

  <joint name="right_front_wheel_joint" type="continuous">
    <origin xyz="0 0 0" rpy="1.5708 0 0" />
    <parent link="right_steering_hinge" />
    <child link="right_front_wheel" />
    <axis xyz="0 0 -1" />
    <limit effort="10" velocity="100"/>
  </joint>

  <xacro:wheel_transmission name="right_front_wheel" />

  <!-- Add Hokuyo laser scanner -->

  <link name="laser">
    <inertial>
      <xacro:hokuyo_inertial_params />
    </inertial>
    <collision>
      <origin xyz="0 0 -0.018" rpy="0 0 0"/>
      <geometry>
        <box size="0.1 0.1 0.1"/>
      </geometry>
    </collision>
    <visual>
      <origin xyz="0 0 -0.018" rpy="0 0 0"/>
      <geometry>
        <mesh filename="model://urdf/meshes/hokuyo.stl"/>
        <material name="grey" />
      </geometry>
    </visual>
  </link>

  <joint name="hokuyo_joint" type="fixed">
    <origin xyz="0.125 0.0 0.173" rpy="0 0 0"/>
    <parent link="chassis" />
    <child link="laser" />
    <axis xyz="0 0 1" />
  </joint>


  <!-- camera class (spawn parameters) -->
  <link name="link">
    <inertial>
      <mass value="1e-5" />
      <origin xyz="0 0 0.25" rpy="0 0 0"/>
      <inertia ixx="1e-6" ixy="0" ixz="0" iyy="1e-6" iyz="0" izz="1e-6" />
    </inertial>
    <collision>
      <origin xyz="0 0 0.25" rpy="0 0 0"/>
      <geometry>
        <box size="0.033 0.175 0.030"/>
      </geometry>
    </collision>
    <visual>
      <origin xyz="0 0 0.025" rpy="0 0 0"/>
      <geometry>
        <box size="0.033 0.175 0.030"/>
      </geometry>
      <material name="red"/>
    </visual>
  </link>

  <joint name="joint" type="fixed">
    <origin xyz="0.390 0 0.025" rpy="0 0 0"/>
    <parent link="chassis"/>
    <child link="link"/>
    <axis xyz="0 0 1" />
    <!-- <limit lower="0.0" upper="0.0" effort="0.0" velocity="0.0" /> -->
  </joint>


  <!-- camera lenses -->
  <link name="camera_link">
    <inertial>
      <mass value="1e-5" />
      <origin xyz="-2.5 0 1.75" rpy="0 .57 0"/>
      <inertia ixx="1e-6" ixy="0" ixz="0" iyy="1e-6" iyz="0" izz="1e-6" />
    </inertial>
  </link>
  <link name="right_link">
    <inertial>
      <mass value="1e-5" />
      <origin xyz="-2.5 0 1.75" rpy="0 .57 0"/>
      <inertia ixx="1e-6" ixy="0" ixz="0" iyy="1e-6" iyz="0" izz="1e-6" />
    </inertial>
  </link>

  <joint name="left_joint" type="fixed">
    <origin xyz="-2.5 0 1.75" rpy="0 .57 0"/>
    <parent link="link"/>
    <child link="camera_link"/>
    <axis xyz="0 0 1" />
  </joint>
  <joint name="right_joint" type="fixed">
    <origin xyz="0 -0.06 0.025" rpy="0 0 0"/>
    <parent link="link"/>
    <child link="right_link"/>
    <axis xyz="0 0 1" />
  </joint>

  <!-- Gazebo references -->

  <gazebo reference="chassis">
    <mu1 value="0.0"/>
    <mu2 value="0.0"/>
    <kp  value="10000000.0" />
    <kd  value="1.0" />
    <material>Gazebo/$(arg robot_skin)</material>
  </gazebo>

  <gazebo reference="left_rear_wheel">
    <mu1 value="1.0"/>
    <mu2 value="1.0"/>
    <kp  value="10000000.0" />
    <kd  value="1.0" />
    <fdir1 value="1 0 0"/>
    <material>Gazebo/Black</material>
  </gazebo>

  <gazebo reference="right_rear_wheel">
    <mu1 value="1.0"/>
    <mu2 value="1.0"/>
    <kp  value="10000000.0" />
    <kd  value="1.0" />
    <fdir1 value="1 0 0"/>
    <material>Gazebo/Black</material>
  </gazebo>

  <gazebo reference="left_front_wheel">
    <mu1 value="1.0"/>
    <mu2 value="1.0"/>
    <kp  value="10000000.0" />
    <kd  value="1.0" />
    <fdir1 value="0 0 1"/>
    <material>Gazebo/Black</material>
  </gazebo>

  <gazebo reference="right_front_wheel">
    <mu1 value="1.0"/>
    <mu2 value="1.0"/>
    <kp  value="10000000.0" />
    <kd  value="1.0" />
    <fdir1 value="0 0 1"/>
    <material>Gazebo/Black</material>
  </gazebo>

  <!-- Gazebo plugins -->

  <gazebo>
    <plugin filename="libgz_ros2_control-system.so" name="gz_ros2_control::GazeboSimROS2ControlPlugin">
      <parameters>$(find ros2_gazebo_sim)/config/control_odom.yaml</parameters>
    </plugin>
  </gazebo>

  <!-- IMU -->
  <gazebo reference="imu_link">
    <sensor name="imu_sensor" type="imu">
      <always_on>true</always_on>
      <update_rate>1</update_rate>
      <topic>imu</topic>
      <imu>
        <angular_velocity>
          <x>
            <noise type="gaussian">
              <mean>0.0</mean>
              <stddev>2e-4</stddev>
              <bias_mean>0.0000075</bias_mean>
              <bias_stddev>0.0000008</bias_stddev>
            </noise>
          </x>
          <y>
            <noise type="gaussian">
              <mean>0.0</mean>
              <stddev>2e-4</stddev>
              <bias_mean>0.0000075</bias_mean>
              <bias_stddev>0.0000008</bias_stddev>
            </noise>
          </y>
          <z>
            <noise type="gaussian">
              <mean>0.0</mean>
              <stddev>2e-4</stddev>
              <bias_mean>0.0000075</bias_mean>
              <bias_stddev>0.0000008</bias_stddev>
            </noise>
          </z>
        </angular_velocity>
        <linear_acceleration>
          <x>
            <noise type="gaussian">
              <mean>0.0</mean>
              <stddev>1.7e-2</stddev>
              <bias_mean>0.1</bias_mean>
              <bias_stddev>0.001</bias_stddev>
            </noise>
          </x>
          <y>
            <noise type="gaussian">
              <mean>0.0</mean>
              <stddev>1.7e-2</stddev>
              <bias_mean>0.1</bias_mean>
              <bias_stddev>0.001</bias_stddev>
            </noise>
          </y>
          <z>
            <noise type="gaussian">
              <mean>0.0</mean>
              <stddev>1.7e-2</stddev>
              <bias_mean>0.1</bias_mean>
              <bias_stddev>0.001</bias_stddev>
            </noise>
          </z>
        </linear_acceleration>
      </imu>
    </sensor>
  </gazebo>

  <!-- hokuyo -->
  <xacro:unless value="$(optenv DISABLE_GAZEBO_LASER false)">
    <gazebo reference="laser">
      <material>Gazebo/Grey</material>
      <sensor type="gpu_lidar" name="hokuyo_sensor">
        <gz_frame_id>laser</gz_frame_id>
        <topic>/scan</topic>
        <pose>0 0 0 0 0 0</pose>
        <visualize>false</visualize>
        <update_rate>40</update_rate>
        <lidar>
          <scan>
            <horizontal>
              <samples>1081</samples>
              <resolution>1</resolution>
              <min_angle>-2.3561944902</min_angle>
              <max_angle>2.3561944902</max_angle>
            </horizontal>
          </scan>
          <range>
            <min>0.1</min>
            <max>30.0</max>
            <resolution>0.01</resolution>
          </range>
          <noise>
            <mean>0.0</mean>
            <stddev>0.01</stddev>
          </noise>
        </lidar>
      </sensor>
    </gazebo>
  </xacro:unless>

  <!-- camera object -->
  <xacro:unless value="$(optenv DISABLE_GAZEBO_CAMERA false)">
    <gazebo reference="camera_link">
      <sensor type="camera" name="left_sensor">
        <topic>/camera/image_raw</topic>
        <update_rate>30.0</update_rate>
        <always_on>true</always_on>
        <visualize>true</visualize>
        <gz_frame_id>camera_link</gz_frame_id>
        <camera name="front_camera">
          <camera_info_topic>/camera_info</camera_info_topic>
          <horizontal_fov>1.74</horizontal_fov>
          <image>
            <width>1920</width>
            <height>1080</height>
            <format>B8G8R8</format>
          </image>
          <clip>
            <near>0.02</near>
            <far>300</far>
          </clip>
          <noise>
            <type>gaussian</type>
            <mean>0.0</mean>
            <stddev>0.007</stddev>
          </noise>
        </camera>
      </sensor>
    </gazebo>
  </xacro:unless>

  <material name="black">
    <color rgba="0.0 0.0 0.0 1.0"/>
  </material>

  <material name="blue">
    <color rgba="0.0 0.0 0.8 1.0"/>
  </material>

  <material name="green">
    <color rgba="0.0 0.8 0.0 1.0"/>
  </material>

  <material name="grey">
    <color rgba="0.2 0.2 0.2 1.0"/>
  </material>

  <material name="orange">
    <color rgba="${255/255} ${108/255} ${10/255} 1.0"/>
  </material>

  <material name="brown">
    <color rgba="${222/255} ${207/255} ${195/255} 1.0"/>
  </material>

  <material name="red">
    <color rgba="0.8 0.0 0.0 1.0"/>
  </material>

  <material name="white">
    <color rgba="1.0 1.0 1.0 1.0"/>
  </material>

</robot>